


export const catchError(fun)=>{
    return ()
}