


export const catchError = (fun)=>{
    return as (req , res , next)=>{
        // fun(req , res).catch((error)=>{
        //     console.log("catchError" , error)
        //   next(error)
        // })
        
    }
}